Workbook
Name Go_details: 'GO details'!$B$1:$H$939
Name GO: 'GO BPOD'!$A$1:$T$251
Name PPO_GO_1: 'PPO-GO'!$F$1:$X$128
Name Shipment_status_1: 'Shipment status'!$B$1:$O$70
Name Shipment_status_2: 'Shipment status'!$B$1028:$B$1030
Name Shipment_status_3: 'Shipment status'!$B$2098:$B$2100
Name Shipment_status_4: 'Shipment status'!$B$567:$B$569
Name Shipment_status_5: 'Shipment status'!$B$1651:$B$1653
Name Shipment_status_6: 'Shipment status'!$B$2598:$B$2600

Sheet Flat knit
B2: GO | C2: =COI!M4
I3: O | L3: F | O3: U | R3: L | T3: C5 | U3: C6 | V3: K | W3: L | X3: Q | Y3: S | Z3: TB | AA3: TC | AB3: TD | AC3: TE | AD3: TF | AE3: TG | AF3: TH | AG3: TI | AH3: TJ | AI3: U | AJ3: U5 | AK3: V
A4: COLOR_DESC | B4: COLOR_CODE | C4: SIZE_CODE1 | D4: % SHORT | E4: % OVER | F4: Gmt QTY | G4: Allow short Q'ty | H4: Order | I4: Collar allocated Q'ty | J4: % Allocate | K4: Order | L4: Cuff allocated Q'ty | M4: % Allocate | N4: Order | O4: Allocated | P4: % Allocate | Q4: Order | R4: Allocated | S4: % Allocate
A5: (blank) | B5: (blank) | C5: (blank) | I5: =MAX(SUMIFS('Shipment status'!$L:$L,'Shipment status'!$A:$A,TRIM(CLEAN(SUBSTITUTE(VLOOKUP($B5&I$3,'PPO-GO'!$A:$AA,12,0)," ",""))),'Shipment status'!$H:$H,I$3,'Shipment status'!$K:$K,'Flat knit'!$C5),SUMIFS('Shipment status'!$L:$L,'Shipment status'!$A:$A,'Flat knit'!$B5,'Shipment status'!$H:$H,I$3,'Shipment status'!$K:$K,'Flat knit'!$C5)) | J5: =IFERROR(I5/$F5,"-") | L5: =MAX(SUMIFS('Shipment status'!$L:$L,'Shipment status'!$A:$A,TRIM(CLEAN(SUBSTITUTE(VLOOKUP($B5&L$3,'PPO-GO'!$A:$AA,12,0)," ",""))),'Shipment status'!$H:$H,L$3,'Shipment status'!$K:$K,'Flat knit'!$C5),SUMIFS('Shipment status'!$L:$L,'Shipment status'!$A:$A,'Flat knit'!$B5,'Shipment status'!$H:$H,L$3,'Shipment status'!$K:$K,'Flat knit'!$C5)) | M5: =IFERROR(IF(L5>I5*1.5,0.5,1)*L5/$F5,"-") | O5: =MAX(SUMIFS('Shipment status'!$L:$L,'Shipment status'!$A:$A,TRIM(CLEAN(SUBSTITUTE(VLOOKUP($B5,'PPO-GO'!$D:$L,9,0)," ",""))),'Shipment status'!$H:$H,O$3,'Shipment status'!$K:$K,'Flat knit'!$C5),SUMIFS('Shipment status'!$L:$L,'Shipment status'!$A:$A,'Flat knit'!$B5,'Shipment status'!$H:$H,O$3,'Shipment status'!$K:$K,'Flat knit'!$C5)) | P5: =IFERROR(O5/$F5,"-") | R5: =MAX(SUMIFS('Shipment status'!$L:$L,'Shipment status'!$A:$A,TRIM(CLEAN(SUBSTITUTE(VLOOKUP($B5,'PPO-GO'!$D:$L,9,0)," ",""))),'Shipment status'!$H:$H,R$3,'Shipment status'!$K:$K,'Flat knit'!$C5),SUMIFS('Shipment status'!$L:$L,'Shipment status'!$A:$A,'Flat knit'!$B5,'Shipment status'!$H:$H,R$3,'Shipment status'!$K:$K,'Flat knit'!$C5)) | S5: =IFERROR(R5/$F5,"-") | T5: =SUMIFS('Shipment status'!$L:$L,'Shipment status'!$A:$A,'Flat knit'!$B5,'Shipment status'!$H:$H,T$3,'Shipment status'!$K:$K,'Flat knit'!$C5) | U5: =SUMIFS('Shipment status'!$L:$L,'Shipment status'!$A:$A,'Flat knit'!$B5,'Shipment status'!$H:$H,U$3,'Shipment status'!$K:$K,'Flat knit'!$C5) | V5: =SUMIFS('Shipment status'!$L:$L,'Shipment status'!$A:$A,'Flat knit'!$B5,'Shipment status'!$H:$H,V$3,'Shipment status'!$K:$K,'Flat knit'!$C5) | W5: =SUMIFS('Shipment status'!$L:$L,'Shipment status'!$A:$A,'Flat knit'!$B5,'Shipment status'!$H:$H,W$3,'Shipment status'!$K:$K,'Flat knit'!$C5) | X5: =SUMIFS('Shipment status'!$L:$L,'Shipment status'!$A:$A,'Flat knit'!$B5,'Shipment status'!$H:$H,X$3,'Shipment status'!$K:$K,'Flat knit'!$C5) | Y5: =SUMIFS('Shipment status'!$L:$L,'Shipment status'!$A:$A,'Flat knit'!$B5,'Shipment status'!$H:$H,Y$3,'Shipment status'!$K:$K,'Flat knit'!$C5) | Z5: =SUMIFS('Shipment status'!$L:$L,'Shipment status'!$A:$A,'Flat knit'!$B5,'Shipment status'!$H:$H,Z$3,'Shipment status'!$K:$K,'Flat knit'!$C5) | AA5: =SUMIFS('Shipment status'!$L:$L,'Shipment status'!$A:$A,'Flat knit'!$B5,'Shipment status'!$H:$H,AA$3,'Shipment status'!$K:$K,'Flat knit'!$C5) | ... AK5: =SUMIFS('Shipment status'!$L:$L,'Shipment status'!$A:$A,'Flat knit'!$B5,'Shipment status'!$H:$H,AK$3,'Shipment status'!$K:$K,'Flat knit'!$C5)
A6: Signature Navy | B6: 26 | C6: XL | D6: 2 | E6: 2 | F6: 1175 | G6: 7.84 | I6: =MAX(SUMIFS('Shipment status'!$L:$L,'Shipment status'!$A:$A,TRIM(CLEAN(SUBSTITUTE(VLOOKUP($B6&I$3,'PPO-GO'!$A:$AA,12,0)," ",""))),'Shipment status'!$H:$H,I$3,'Shipment status'!$K:$K,'Flat knit'!$C6),SUMIFS('Shipment status'!$L:$L,'Shipment status'!$A:$A,'Flat knit'!$B6,'Shipment status'!$H:$H,I$3,'Shipment status'!$K:$K,'Flat knit'!$C6)) | J6: =IFERROR(I6/$F6,"-") | L6: =MAX(SUMIFS('Shipment status'!$L:$L,'Shipment status'!$A:$A,TRIM(CLEAN(SUBSTITUTE(VLOOKUP($B6&L$3,'PPO-GO'!$A:$AA,12,0)," ",""))),'Shipment status'!$H:$H,L$3,'Shipment status'!$K:$K,'Flat knit'!$C6),SUMIFS('Shipment status'!$L:$L,'Shipment status'!$A:$A,'Flat knit'!$B6,'Shipment status'!$H:$H,L$3,'Shipment status'!$K:$K,'Flat knit'!$C6)) | M6: =IFERROR(IF(L6>I6*1.5,0.5,1)*L6/$F6,"-") | O6: =MAX(SUMIFS('Shipment status'!$L:$L,'Shipment status'!$A:$A,TRIM(CLEAN(SUBSTITUTE(VLOOKUP($B6,'PPO-GO'!$D:$L,9,0)," ",""))),'Shipment status'!$H:$H,O$3,'Shipment status'!$K:$K,'Flat knit'!$C6),SUMIFS('Shipment status'!$L:$L,'Shipment status'!$A:$A,'Flat knit'!$B6,'Shipment status'!$H:$H,O$3,'Shipment status'!$K:$K,'Flat knit'!$C6)) | P6: =IFERROR(O6/$F6,"-") | R6: =MAX(SUMIFS('Shipment status'!$L:$L,'Shipment status'!$A:$A,TRIM(CLEAN(SUBSTITUTE(VLOOKUP($B6,'PPO-GO'!$D:$L,9,0)," ",""))),'Shipment status'!$H:$H,R$3,'Shipment status'!$K:$K,'Flat knit'!$C6),SUMIFS('Shipment status'!$L:$L,'Shipment status'!$A:$A,'Flat knit'!$B6,'Shipment status'!$H:$H,R$3,'Shipment status'!$K:$K,'Flat knit'!$C6)) | S6: =IFERROR(R6/$F6,"-") | T6: =SUMIFS('Shipment status'!$L:$L,'Shipment status'!$A:$A,'Flat knit'!$B6,'Shipment status'!$H:$H,T$3,'Shipment status'!$K:$K,'Flat knit'!$C6) | U6: =SUMIFS('Shipment status'!$L:$L,'Shipment status'!$A:$A,'Flat knit'!$B6,'Shipment status'!$H:$H,U$3,'Shipment status'!$K:$K,'Flat knit'!$C6) | V6: =SUMIFS('Shipment status'!$L:$L,'Shipment status'!$A:$A,'Flat knit'!$B6,'Shipment status'!$H:$H,V$3,'Shipment status'!$K:$K,'Flat knit'!$C6) | W6: =SUMIFS('Shipment status'!$L:$L,'Shipment status'!$A:$A,'Flat knit'!$B6,'Shipment status'!$H:$H,W$3,'Shipment status'!$K:$K,'Flat knit'!$C6) | X6: =SUMIFS('Shipment status'!$L:$L,'Shipment status'!$A:$A,'Flat knit'!$B6,'Shipment status'!$H:$H,X$3,'Shipment status'!$K:$K,'Flat knit'!$C6) | Y6: =SUMIFS('Shipment status'!$L:$L,'Shipment status'!$A:$A,'Flat knit'!$B6,'Shipment status'!$H:$H,Y$3,'Shipment status'!$K:$K,'Flat knit'!$C6) | Z6: =SUMIFS('Shipment status'!$L:$L,'Shipment status'!$A:$A,'Flat knit'!$B6,'Shipment status'!$H:$H,Z$3,'Shipment status'!$K:$K,'Flat knit'!$C6) | AA6: =SUMIFS('Shipment status'!$L:$L,'Shipment status'!$A:$A,'Flat knit'!$B6,'Shipment status'!$H:$H,AA$3,'Shipment status'!$K:$K,'Flat knit'!$C6) | ... AK6: =SUMIFS('Shipment status'!$L:$L,'Shipment status'!$A:$A,'Flat knit'!$B6,'Shipment status'!$H:$H,AK$3,'Shipment status'!$K:$K,'Flat knit'!$C6)
A7: Signature Navy | B7: 26 | C7: S | D7: 2 | E7: 2 | F7: 580 | G7: 2.04 | I7: =MAX(SUMIFS('Shipment status'!$L:$L,'Shipment status'!$A:$A,TRIM(CLEAN(SUBSTITUTE(VLOOKUP($B7&I$3,'PPO-GO'!$A:$AA,12,0)," ",""))),'Shipment status'!$H:$H,I$3,'Shipment status'!$K:$K,'Flat knit'!$C7),SUMIFS('Shipment status'!$L:$L,'Shipment status'!$A:$A,'Flat knit'!$B7,'Shipment status'!$H:$H,I$3,'Shipment status'!$K:$K,'Flat knit'!$C7)) | J7: =IFERROR(I7/$F7,"-") | L7: =MAX(SUMIFS('Shipment status'!$L:$L,'Shipment status'!$A:$A,TRIM(CLEAN(SUBSTITUTE(VLOOKUP($B7&L$3,'PPO-GO'!$A:$AA,12,0)," ",""))),'Shipment status'!$H:$H,L$3,'Shipment status'!$K:$K,'Flat knit'!$C7),SUMIFS('Shipment status'!$L:$L,'Shipment status'!$A:$A,'Flat knit'!$B7,'Shipment status'!$H:$H,L$3,'Shipment status'!$K:$K,'Flat knit'!$C7)) | M7: =IFERROR(IF(L7>I7*1.5,0.5,1)*L7/$F7,"-") | O7: =MAX(SUMIFS('Shipment status'!$L:$L,'Shipment status'!$A:$A,TRIM(CLEAN(SUBSTITUTE(VLOOKUP($B7,'PPO-GO'!$D:$L,9,0)," ",""))),'Shipment status'!$H:$H,O$3,'Shipment status'!$K:$K,'Flat knit'!$C7),SUMIFS('Shipment status'!$L:$L,'Shipment status'!$A:$A,'Flat knit'!$B7,'Shipment status'!$H:$H,O$3,'Shipment status'!$K:$K,'Flat knit'!$C7)) | P7: =IFERROR(O7/$F7,"-") | R7: =MAX(SUMIFS('Shipment status'!$L:$L,'Shipment status'!$A:$A,TRIM(CLEAN(SUBSTITUTE(VLOOKUP($B7,'PPO-GO'!$D:$L,9,0)," ",""))),'Shipment status'!$H:$H,R$3,'Shipment status'!$K:$K,'Flat knit'!$C7),SUMIFS('Shipment status'!$L:$L,'Shipment status'!$A:$A,'Flat knit'!$B7,'Shipment status'!$H:$H,R$3,'Shipment status'!$K:$K,'Flat knit'!$C7)) | S7: =IFERROR(R7/$F7,"-") | T7: =SUMIFS('Shipment status'!$L:$L,'Shipment status'!$A:$A,'Flat knit'!$B7,'Shipment status'!$H:$H,T$3,'Shipment status'!$K:$K,'Flat knit'!$C7) | U7: =SUMIFS('Shipment status'!$L:$L,'Shipment status'!$A:$A,'Flat knit'!$B7,'Shipment status'!$H:$H,U$3,'Shipment status'!$K:$K,'Flat knit'!$C7) | V7: =SUMIFS('Shipment status'!$L:$L,'Shipment status'!$A:$A,'Flat knit'!$B7,'Shipment status'!$H:$H,V$3,'Shipment status'!$K:$K,'Flat knit'!$C7) | W7: =SUMIFS('Shipment status'!$L:$L,'Shipment status'!$A:$A,'Flat knit'!$B7,'Shipment status'!$H:$H,W$3,'Shipment status'!$K:$K,'Flat knit'!$C7) | X7: =SUMIFS('Shipment status'!$L:$L,'Shipment status'!$A:$A,'Flat knit'!$B7,'Shipment status'!$H:$H,X$3,'Shipment status'!$K:$K,'Flat knit'!$C7) | Y7: =SUMIFS('Shipment status'!$L:$L,'Shipment status'!$A:$A,'Flat knit'!$B7,'Shipment status'!$H:$H,Y$3,'Shipment status'!$K:$K,'Flat knit'!$C7) | Z7: =SUMIFS('Shipment status'!$L:$L,'Shipment status'!$A:$A,'Flat knit'!$B7,'Shipment status'!$H:$H,Z$3,'Shipment status'!$K:$K,'Flat knit'!$C7) | AA7: =SUMIFS('Shipment status'!$L:$L,'Shipment status'!$A:$A,'Flat knit'!$B7,'Shipment status'!$H:$H,AA$3,'Shipment status'!$K:$K,'Flat knit'!$C7) | ... AK7: =SUMIFS('Shipment status'!$L:$L,'Shipment status'!$A:$A,'Flat knit'!$B7,'Shipment status'!$H:$H,AK$3,'Shipment status'!$K:$K,'Flat knit'!$C7)
A8: Signature Navy | B8: 26 | C8: M | D8: 2 | E8: 2 | F8: 1200 | G8: 7.26 | I8: =MAX(SUMIFS('Shipment status'!$L:$L,'Shipment status'!$A:$A,TRIM(CLEAN(SUBSTITUTE(VLOOKUP($B8&I$3,'PPO-GO'!$A:$AA,12,0)," ",""))),'Shipment status'!$H:$H,I$3,'Shipment status'!$K:$K,'Flat knit'!$C8),SUMIFS('Shipment status'!$L:$L,'Shipment status'!$A:$A,'Flat knit'!$B8,'Shipment status'!$H:$H,I$3,'Shipment status'!$K:$K,'Flat knit'!$C8)) | J8: =IFERROR(I8/$F8,"-") | L8: =MAX(SUMIFS('Shipment status'!$L:$L,'Shipment status'!$A:$A,TRIM(CLEAN(SUBSTITUTE(VLOOKUP($B8&L$3,'PPO-GO'!$A:$AA,12,0)," ",""))),'Shipment status'!$H:$H,L$3,'Shipment status'!$K:$K,'Flat knit'!$C8),SUMIFS('Shipment status'!$L:$L,'Shipment status'!$A:$A,'Flat knit'!$B8,'Shipment status'!$H:$H,L$3,'Shipment status'!$K:$K,'Flat knit'!$C8)) | M8: =IFERROR(IF(L8>I8*1.5,0.5,1)*L8/$F8,"-") | O8: =MAX(SUMIFS('Shipment status'!$L:$L,'Shipment status'!$A:$A,TRIM(CLEAN(SUBSTITUTE(VLOOKUP($B8,'PPO-GO'!$D:$L,9,0)," ",""))),'Shipment status'!$H:$H,O$3,'Shipment status'!$K:$K,'Flat knit'!$C8),SUMIFS('Shipment status'!$L:$L,'Shipment status'!$A:$A,'Flat knit'!$B8,'Shipment status'!$H:$H,O$3,'Shipment status'!$K:$K,'Flat knit'!$C8)) | P8: =IFERROR(O8/$F8,"-") | R8: =MAX(SUMIFS('Shipment status'!$L:$L,'Shipment status'!$A:$A,TRIM(CLEAN(SUBSTITUTE(VLOOKUP($B8,'PPO-GO'!$D:$L,9,0)," ",""))),'Shipment status'!$H:$H,R$3,'Shipment status'!$K:$K,'Flat knit'!$C8),SUMIFS('Shipment status'!$L:$L,'Shipment status'!$A:$A,'Flat knit'!$B8,'Shipment status'!$H:$H,R$3,'Shipment status'!$K:$K,'Flat knit'!$C8)) | S8: =IFERROR(R8/$F8,"-") | T8: =SUMIFS('Shipment status'!$L:$L,'Shipment status'!$A:$A,'Flat knit'!$B8,'Shipment status'!$H:$H,T$3,'Shipment status'!$K:$K,'Flat knit'!$C8) | U8: =SUMIFS('Shipment status'!$L:$L,'Shipment status'!$A:$A,'Flat knit'!$B8,'Shipment status'!$H:$H,U$3,'Shipment status'!$K:$K,'Flat knit'!$C8) | V8: =SUMIFS('Shipment status'!$L:$L,'Shipment status'!$A:$A,'Flat knit'!$B8,'Shipment status'!$H:$H,V$3,'Shipment status'!$K:$K,'Flat knit'!$C8) | W8: =SUMIFS('Shipment status'!$L:$L,'Shipment status'!$A:$A,'Flat knit'!$B8,'Shipment status'!$H:$H,W$3,'Shipment status'!$K:$K,'Flat knit'!$C8) | X8: =SUMIFS('Shipment status'!$L:$L,'Shipment status'!$A:$A,'Flat knit'!$B8,'Shipment status'!$H:$H,X$3,'Shipment status'!$K:$K,'Flat knit'!$C8) | Y8: =SUMIFS('Shipment status'!$L:$L,'Shipment status'!$A:$A,'Flat knit'!$B8,'Shipment status'!$H:$H,Y$3,'Shipment status'!$K:$K,'Flat knit'!$C8) | Z8: =SUMIFS('Shipment status'!$L:$L,'Shipment status'!$A:$A,'Flat knit'!$B8,'Shipment status'!$H:$H,Z$3,'Shipment status'!$K:$K,'Flat knit'!$C8) | AA8: =SUMIFS('Shipment status'!$L:$L,'Shipment status'!$A:$A,'Flat knit'!$B8,'Shipment status'!$H:$H,AA$3,'Shipment status'!$K:$K,'Flat knit'!$C8) | ... AK8: =SUMIFS('Shipment status'!$L:$L,'Shipment status'!$A:$A,'Flat knit'!$B8,'Shipment status'!$H:$H,AK$3,'Shipment status'!$K:$K,'Flat knit'!$C8)
A9: Signature Navy | B9: 26 | C9: L | D9: 2 | E9: 2 | F9: 1448 | G9: 9.12 | I9: =MAX(SUMIFS('Shipment status'!$L:$L,'Shipment status'!$A:$A,TRIM(CLEAN(SUBSTITUTE(VLOOKUP($B9&I$3,'PPO-GO'!$A:$AA,12,0)," ",""))),'Shipment status'!$H:$H,I$3,'Shipment status'!$K:$K,'Flat knit'!$C9),SUMIFS('Shipment status'!$L:$L,'Shipment status'!$A:$A,'Flat knit'!$B9,'Shipment status'!$H:$H,I$3,'Shipment status'!$K:$K,'Flat knit'!$C9)) | J9: =IFERROR(I9/$F9,"-") | L9: =MAX(SUMIFS('Shipment status'!$L:$L,'Shipment status'!$A:$A,TRIM(CLEAN(SUBSTITUTE(VLOOKUP($B9&L$3,'PPO-GO'!$A:$AA,12,0)," ",""))),'Shipment status'!$H:$H,L$3,'Shipment status'!$K:$K,'Flat knit'!$C9),SUMIFS('Shipment status'!$L:$L,'Shipment status'!$A:$A,'Flat knit'!$B9,'Shipment status'!$H:$H,L$3,'Shipment status'!$K:$K,'Flat knit'!$C9)) | M9: =IFERROR(IF(L9>I9*1.5,0.5,1)*L9/$F9,"-") | O9: =MAX(SUMIFS('Shipment status'!$L:$L,'Shipment status'!$A:$A,TRIM(CLEAN(SUBSTITUTE(VLOOKUP($B9,'PPO-GO'!$D:$L,9,0)," ",""))),'Shipment status'!$H:$H,O$3,'Shipment status'!$K:$K,'Flat knit'!$C9),SUMIFS('Shipment status'!$L:$L,'Shipment status'!$A:$A,'Flat knit'!$B9,'Shipment status'!$H:$H,O$3,'Shipment status'!$K:$K,'Flat knit'!$C9)) | P9: =IFERROR(O9/$F9,"-") | R9: =MAX(SUMIFS('Shipment status'!$L:$L,'Shipment status'!$A:$A,TRIM(CLEAN(SUBSTITUTE(VLOOKUP($B9,'PPO-GO'!$D:$L,9,0)," ",""))),'Shipment status'!$H:$H,R$3,'Shipment status'!$K:$K,'Flat knit'!$C9),SUMIFS('Shipment status'!$L:$L,'Shipment status'!$A:$A,'Flat knit'!$B9,'Shipment status'!$H:$H,R$3,'Shipment status'!$K:$K,'Flat knit'!$C9)) | S9: =IFERROR(R9/$F9,"-") | T9: =SUMIFS('Shipment status'!$L:$L,'Shipment status'!$A:$A,'Flat knit'!$B9,'Shipment status'!$H:$H,T$3,'Shipment status'!$K:$K,'Flat knit'!$C9) | U9: =SUMIFS('Shipment status'!$L:$L,'Shipment status'!$A:$A,'Flat knit'!$B9,'Shipment status'!$H:$H,U$3,'Shipment status'!$K:$K,'Flat knit'!$C9) | V9: =SUMIFS('Shipment status'!$L:$L,'Shipment status'!$A:$A,'Flat knit'!$B9,'Shipment status'!$H:$H,V$3,'Shipment status'!$K:$K,'Flat knit'!$C9) | W9: =SUMIFS('Shipment status'!$L:$L,'Shipment status'!$A:$A,'Flat knit'!$B9,'Shipment status'!$H:$H,W$3,'Shipment status'!$K:$K,'Flat knit'!$C9) | X9: =SUMIFS('Shipment status'!$L:$L,'Shipment status'!$A:$A,'Flat knit'!$B9,'Shipment status'!$H:$H,X$3,'Shipment status'!$K:$K,'Flat knit'!$C9) | Y9: =SUMIFS('Shipment status'!$L:$L,'Shipment status'!$A:$A,'Flat knit'!$B9,'Shipment status'!$H:$H,Y$3,'Shipment status'!$K:$K,'Flat knit'!$C9) | Z9: =SUMIFS('Shipment status'!$L:$L,'Shipment status'!$A:$A,'Flat knit'!$B9,'Shipment status'!$H:$H,Z$3,'Shipment status'!$K:$K,'Flat knit'!$C9) | AA9: =SUMIFS('Shipment status'!$L:$L,'Shipment status'!$A:$A,'Flat knit'!$B9,'Shipment status'!$H:$H,AA$3,'Shipment status'!$K:$K,'Flat knit'!$C9) | ... AK9: =SUMIFS('Shipment status'!$L:$L,'Shipment status'!$A:$A,'Flat knit'!$B9,'Shipment status'!$H:$H,AK$3,'Shipment status'!$K:$K,'Flat knit'!$C9)
A10: Signature Navy | B10: 26 | C10: TTL | D10: 2 | E10: 2 | F10: 2000 | I10: =MAX(SUMIFS('Shipment status'!$L:$L,'Shipment status'!$A:$A,TRIM(CLEAN(SUBSTITUTE(VLOOKUP($B10&I$3,'PPO-GO'!$A:$AA,12,0)," ",""))),'Shipment status'!$H:$H,I$3,'Shipment status'!$K:$K,'Flat knit'!$C10),SUMIFS('Shipment status'!$L:$L,'Shipment status'!$A:$A,'Flat knit'!$B10,'Shipment status'!$H:$H,I$3,'Shipment status'!$K:$K,'Flat knit'!$C10)) | J10: =IFERROR(I10/$F10,"-") | L10: =MAX(SUMIFS('Shipment status'!$L:$L,'Shipment status'!$A:$A,TRIM(CLEAN(SUBSTITUTE(VLOOKUP($B10&L$3,'PPO-GO'!$A:$AA,12,0)," ",""))),'Shipment status'!$H:$H,L$3,'Shipment status'!$K:$K,'Flat knit'!$C10),SUMIFS('Shipment status'!$L:$L,'Shipment status'!$A:$A,'Flat knit'!$B10,'Shipment status'!$H:$H,L$3,'Shipment status'!$K:$K,'Flat knit'!$C10)) | M10: =IFERROR(IF(L10>I10*1.5,0.5,1)*L10/$F10,"-") | O10: =MAX(SUMIFS('Shipment status'!$L:$L,'Shipment status'!$A:$A,TRIM(CLEAN(SUBSTITUTE(VLOOKUP($B10,'PPO-GO'!$D:$L,9,0)," ",""))),'Shipment status'!$H:$H,O$3,'Shipment status'!$K:$K,'Flat knit'!$C10),SUMIFS('Shipment status'!$L:$L,'Shipment status'!$A:$A,'Flat knit'!$B10,'Shipment status'!$H:$H,O$3,'Shipment status'!$K:$K,'Flat knit'!$C10)) | P10: =IFERROR(O10/$F10,"-") | R10: =MAX(SUMIFS('Shipment status'!$L:$L,'Shipment status'!$A:$A,TRIM(CLEAN(SUBSTITUTE(VLOOKUP($B10,'PPO-GO'!$D:$L,9,0)," ",""))),'Shipment status'!$H:$H,R$3,'Shipment status'!$K:$K,'Flat knit'!$C10),SUMIFS('Shipment status'!$L:$L,'Shipment status'!$A:$A,'Flat knit'!$B10,'Shipment status'!$H:$H,R$3,'Shipment status'!$K:$K,'Flat knit'!$C10)) | S10: =IFERROR(R10/$F10,"-") | T10: =SUMIFS('Shipment status'!$L:$L,'Shipment status'!$A:$A,'Flat knit'!$B10,'Shipment status'!$H:$H,T$3,'Shipment status'!$K:$K,'Flat knit'!$C10) | U10: =SUMIFS('Shipment status'!$L:$L,'Shipment status'!$A:$A,'Flat knit'!$B10,'Shipment status'!$H:$H,U$3,'Shipment status'!$K:$K,'Flat knit'!$C10) | V10: =SUMIFS('Shipment status'!$L:$L,'Shipment status'!$A:$A,'Flat knit'!$B10,'Shipment status'!$H:$H,V$3,'Shipment status'!$K:$K,'Flat knit'!$C10) | W10: =SUMIFS('Shipment status'!$L:$L,'Shipment status'!$A:$A,'Flat knit'!$B10,'Shipment status'!$H:$H,W$3,'Shipment status'!$K:$K,'Flat knit'!$C10) | X10: =SUMIFS('Shipment status'!$L:$L,'Shipment status'!$A:$A,'Flat knit'!$B10,'Shipment status'!$H:$H,X$3,'Shipment status'!$K:$K,'Flat knit'!$C10) | Y10: =SUMIFS('Shipment status'!$L:$L,'Shipment status'!$A:$A,'Flat knit'!$B10,'Shipment status'!$H:$H,Y$3,'Shipment status'!$K:$K,'Flat knit'!$C10) | Z10: =SUMIFS('Shipment status'!$L:$L,'Shipment status'!$A:$A,'Flat knit'!$B10,'Shipment status'!$H:$H,Z$3,'Shipment status'!$K:$K,'Flat knit'!$C10) | AA10: =SUMIFS('Shipment status'!$L:$L,'Shipment status'!$A:$A,'Flat knit'!$B10,'Shipment status'!$H:$H,AA$3,'Shipment status'!$K:$K,'Flat knit'!$C10) | ... AK10: =SUMIFS('Shipment status'!$L:$L,'Shipment status'!$A:$A,'Flat knit'!$B10,'Shipment status'!$H:$H,AK$3,'Shipment status'!$K:$K,'Flat knit'!$C10)
A11: Signature Navy | B11: 26 | C11: XXXL | D11: 2 | E11: 2 | F11: 181 | G11: 2.6 | I11: =MAX(SUMIFS('Shipment status'!$L:$L,'Shipment status'!$A:$A,TRIM(CLEAN(SUBSTITUTE(VLOOKUP($B11&I$3,'PPO-GO'!$A:$AA,12,0)," ",""))),'Shipment status'!$H:$H,I$3,'Shipment status'!$K:$K,'Flat knit'!$C11),SUMIFS('Shipment status'!$L:$L,'Shipment status'!$A:$A,'Flat knit'!$B11,'Shipment status'!$H:$H,I$3,'Shipment status'!$K:$K,'Flat knit'!$C11)) | J11: =IFERROR(I11/$F11,"-") | L11: =MAX(SUMIFS('Shipment status'!$L:$L,'Shipment status'!$A:$A,TRIM(CLEAN(SUBSTITUTE(VLOOKUP($B11&L$3,'PPO-GO'!$A:$AA,12,0)," ",""))),'Shipment status'!$H:$H,L$3,'Shipment status'!$K:$K,'Flat knit'!$C11),SUMIFS('Shipment status'!$L:$L,'Shipment status'!$A:$A,'Flat knit'!$B11,'Shipment status'!$H:$H,L$3,'Shipment status'!$K:$K,'Flat knit'!$C11)) | M11: =IFERROR(IF(L11>I11*1.5,0.5,1)*L11/$F11,"-") | O11: =MAX(SUMIFS('Shipment status'!$L:$L,'Shipment status'!$A:$A,TRIM(CLEAN(SUBSTITUTE(VLOOKUP($B11,'PPO-GO'!$D:$L,9,0)," ",""))),'Shipment status'!$H:$H,O$3,'Shipment status'!$K:$K,'Flat knit'!$C11),SUMIFS('Shipment status'!$L:$L,'Shipment status'!$A:$A,'Flat knit'!$B11,'Shipment status'!$H:$H,O$3,'Shipment status'!$K:$K,'Flat knit'!$C11)) | P11: =IFERROR(O11/$F11,"-") | R11: =MAX(SUMIFS('Shipment status'!$L:$L,'Shipment status'!$A:$A,TRIM(CLEAN(SUBSTITUTE(VLOOKUP($B11,'PPO-GO'!$D:$L,9,0)," ",""))),'Shipment status'!$H:$H,R$3,'Shipment status'!$K:$K,'Flat knit'!$C11),SUMIFS('Shipment status'!$L:$L,'Shipment status'!$A:$A,'Flat knit'!$B11,'Shipment status'!$H:$H,R$3,'Shipment status'!$K:$K,'Flat knit'!$C11)) | S11: =IFERROR(R11/$F11,"-") | T11: =SUMIFS('Shipment status'!$L:$L,'Shipment status'!$A:$A,'Flat knit'!$B11,'Shipment status'!$H:$H,T$3,'Shipment status'!$K:$K,'Flat knit'!$C11) | U11: =SUMIFS('Shipment status'!$L:$L,'Shipment status'!$A:$A,'Flat knit'!$B11,'Shipment status'!$H:$H,U$3,'Shipment status'!$K:$K,'Flat knit'!$C11) | V11: =SUMIFS('Shipment status'!$L:$L,'Shipment status'!$A:$A,'Flat knit'!$B11,'Shipment status'!$H:$H,V$3,'Shipment status'!$K:$K,'Flat knit'!$C11) | W11: =SUMIFS('Shipment status'!$L:$L,'Shipment status'!$A:$A,'Flat knit'!$B11,'Shipment status'!$H:$H,W$3,'Shipment status'!$K:$K,'Flat knit'!$C11) | X11: =SUMIFS('Shipment status'!$L:$L,'Shipment status'!$A:$A,'Flat knit'!$B11,'Shipment status'!$H:$H,X$3,'Shipment status'!$K:$K,'Flat knit'!$C11) | Y11: =SUMIFS('Shipment status'!$L:$L,'Shipment status'!$A:$A,'Flat knit'!$B11,'Shipment status'!$H:$H,Y$3,'Shipment status'!$K:$K,'Flat knit'!$C11) | Z11: =SUMIFS('Shipment status'!$L:$L,'Shipment status'!$A:$A,'Flat knit'!$B11,'Shipment status'!$H:$H,Z$3,'Shipment status'!$K:$K,'Flat knit'!$C11) | AA11: =SUMIFS('Shipment status'!$L:$L,'Shipment status'!$A:$A,'Flat knit'!$B11,'Shipment status'!$H:$H,AA$3,'Shipment status'!$K:$K,'Flat knit'!$C11) | ... AK11: =SUMIFS('Shipment status'!$L:$L,'Shipment status'!$A:$A,'Flat knit'!$B11,'Shipment status'!$H:$H,AK$3,'Shipment status'!$K:$K,'Flat knit'!$C11)
A12: Signature Navy | B12: 26 | C12: 2XL | D12: 2 | E12: 2 | F12: 789 | G12: 4.46 | I12: =MAX(SUMIFS('Shipment status'!$L:$L,'Shipment status'!$A:$A,TRIM(CLEAN(SUBSTITUTE(VLOOKUP($B12&I$3,'PPO-GO'!$A:$AA,12,0)," ",""))),'Shipment status'!$H:$H,I$3,'Shipment status'!$K:$K,'Flat knit'!$C12),SUMIFS('Shipment status'!$L:$L,'Shipment status'!$A:$A,'Flat knit'!$B12,'Shipment status'!$H:$H,I$3,'Shipment status'!$K:$K,'Flat knit'!$C12)) | J12: =IFERROR(I12/$F12,"-") | L12: =MAX(SUMIFS('Shipment status'!$L:$L,'Shipment status'!$A:$A,TRIM(CLEAN(SUBSTITUTE(VLOOKUP($B12&L$3,'PPO-GO'!$A:$AA,12,0)," ",""))),'Shipment status'!$H:$H,L$3,'Shipment status'!$K:$K,'Flat knit'!$C12),SUMIFS('Shipment status'!$L:$L,'Shipment status'!$A:$A,'Flat knit'!$B12,'Shipment status'!$H:$H,L$3,'Shipment status'!$K:$K,'Flat knit'!$C12)) | M12: =IFERROR(IF(L12>I12*1.5,0.5,1)*L12/$F12,"-") | O12: =MAX(SUMIFS('Shipment status'!$L:$L,'Shipment status'!$A:$A,TRIM(CLEAN(SUBSTITUTE(VLOOKUP($B12,'PPO-GO'!$D:$L,9,0)," ",""))),'Shipment status'!$H:$H,O$3,'Shipment status'!$K:$K,'Flat knit'!$C12),SUMIFS('Shipment status'!$L:$L,'Shipment status'!$A:$A,'Flat knit'!$B12,'Shipment status'!$H:$H,O$3,'Shipment status'!$K:$K,'Flat knit'!$C12)) | P12: =IFERROR(O12/$F12,"-") | R12: =MAX(SUMIFS('Shipment status'!$L:$L,'Shipment status'!$A:$A,TRIM(CLEAN(SUBSTITUTE(VLOOKUP($B12,'PPO-GO'!$D:$L,9,0)," ",""))),'Shipment status'!$H:$H,R$3,'Shipment status'!$K:$K,'Flat knit'!$C12),SUMIFS('Shipment status'!$L:$L,'Shipment status'!$A:$A,'Flat knit'!$B12,'Shipment status'!$H:$H,R$3,'Shipment status'!$K:$K,'Flat knit'!$C12)) | S12: =IFERROR(R12/$F12,"-") | T12: =SUMIFS('Shipment status'!$L:$L,'Shipment status'!$A:$A,'Flat knit'!$B12,'Shipment status'!$H:$H,T$3,'Shipment status'!$K:$K,'Flat knit'!$C12) | U12: =SUMIFS('Shipment status'!$L:$L,'Shipment status'!$A:$A,'Flat knit'!$B12,'Shipment status'!$H:$H,U$3,'Shipment status'!$K:$K,'Flat knit'!$C12) | V12: =SUMIFS('Shipment status'!$L:$L,'Shipment status'!$A:$A,'Flat knit'!$B12,'Shipment status'!$H:$H,V$3,'Shipment status'!$K:$K,'Flat knit'!$C12) | W12: =SUMIFS('Shipment status'!$L:$L,'Shipment status'!$A:$A,'Flat knit'!$B12,'Shipment status'!$H:$H,W$3,'Shipment status'!$K:$K,'Flat knit'!$C12) | X12: =SUMIFS('Shipment status'!$L:$L,'Shipment status'!$A:$A,'Flat knit'!$B12,'Shipment status'!$H:$H,X$3,'Shipment status'!$K:$K,'Flat knit'!$C12) | Y12: =SUMIFS('Shipment status'!$L:$L,'Shipment status'!$A:$A,'Flat knit'!$B12,'Shipment status'!$H:$H,Y$3,'Shipment status'!$K:$K,'Flat knit'!$C12) | Z12: =SUMIFS('Shipment status'!$L:$L,'Shipment status'!$A:$A,'Flat knit'!$B12,'Shipment status'!$H:$H,Z$3,'Shipment status'!$K:$K,'Flat knit'!$C12) | AA12: =SUMIFS('Shipment status'!$L:$L,'Shipment status'!$A:$A,'Flat knit'!$B12,'Shipment status'!$H:$H,AA$3,'Shipment status'!$K:$K,'Flat knit'!$C12) | ... AK12: =SUMIFS('Shipment status'!$L:$L,'Shipment status'!$A:$A,'Flat knit'!$B12,'Shipment status'!$H:$H,AK$3,'Shipment status'!$K:$K,'Flat knit'!$C12)
A13: Signature White | B13: 1 | C13: XL | D13: 2 | E13: 2 | F13: 2736 | G13: 14.72 | I13: =MAX(SUMIFS('Shipment status'!$L:$L,'Shipment status'!$A:$A,TRIM(CLEAN(SUBSTITUTE(VLOOKUP($B13&I$3,'PPO-GO'!$A:$AA,12,0)," ",""))),'Shipment status'!$H:$H,I$3,'Shipment status'!$K:$K,'Flat knit'!$C13),SUMIFS('Shipment status'!$L:$L,'Shipment status'!$A:$A,'Flat knit'!$B13,'Shipment status'!$H:$H,I$3,'Shipment status'!$K:$K,'Flat knit'!$C13)) | J13: =IFERROR(I13/$F13,"-") | L13: =MAX(SUMIFS('Shipment status'!$L:$L,'Shipment status'!$A:$A,TRIM(CLEAN(SUBSTITUTE(VLOOKUP($B13&L$3,'PPO-GO'!$A:$AA,12,0)," ",""))),'Shipment status'!$H:$H,L$3,'Shipment status'!$K:$K,'Flat knit'!$C13),SUMIFS('Shipment status'!$L:$L,'Shipment status'!$A:$A,'Flat knit'!$B13,'Shipment status'!$H:$H,L$3,'Shipment status'!$K:$K,'Flat knit'!$C13)) | M13: =IFERROR(IF(L13>I13*1.5,0.5,1)*L13/$F13,"-") | O13: =MAX(SUMIFS('Shipment status'!$L:$L,'Shipment status'!$A:$A,TRIM(CLEAN(SUBSTITUTE(VLOOKUP($B13,'PPO-GO'!$D:$L,9,0)," ",""))),'Shipment status'!$H:$H,O$3,'Shipment status'!$K:$K,'Flat knit'!$C13),SUMIFS('Shipment status'!$L:$L,'Shipment status'!$A:$A,'Flat knit'!$B13,'Shipment status'!$H:$H,O$3,'Shipment status'!$K:$K,'Flat knit'!$C13)) | P13: =IFERROR(O13/$F13,"-") | R13: =MAX(SUMIFS('Shipment status'!$L:$L,'Shipment status'!$A:$A,TRIM(CLEAN(SUBSTITUTE(VLOOKUP($B13,'PPO-GO'!$D:$L,9,0)," ",""))),'Shipment status'!$H:$H,R$3,'Shipment status'!$K:$K,'Flat knit'!$C13),SUMIFS('Shipment status'!$L:$L,'Shipment status'!$A:$A,'Flat knit'!$B13,'Shipment status'!$H:$H,R$3,'Shipment status'!$K:$K,'Flat knit'!$C13)) | S13: =IFERROR(R13/$F13,"-") | T13: =SUMIFS('Shipment status'!$L:$L,'Shipment status'!$A:$A,'Flat knit'!$B13,'Shipment status'!$H:$H,T$3,'Shipment status'!$K:$K,'Flat knit'!$C13) | U13: =SUMIFS('Shipment status'!$L:$L,'Shipment status'!$A:$A,'Flat knit'!$B13,'Shipment status'!$H:$H,U$3,'Shipment status'!$K:$K,'Flat knit'!$C13) | V13: =SUMIFS('Shipment status'!$L:$L,'Shipment status'!$A:$A,'Flat knit'!$B13,'Shipment status'!$H:$H,V$3,'Shipment status'!$K:$K,'Flat knit'!$C13) | W13: =SUMIFS('Shipment status'!$L:$L,'Shipment status'!$A:$A,'Flat knit'!$B13,'Shipment status'!$H:$H,W$3,'Shipment status'!$K:$K,'Flat knit'!$C13) | X13: =SUMIFS('Shipment status'!$L:$L,'Shipment status'!$A:$A,'Flat knit'!$B13,'Shipment status'!$H:$H,X$3,'Shipment status'!$K:$K,'Flat knit'!$C13) | Y13: =SUMIFS('Shipment status'!$L:$L,'Shipment status'!$A:$A,'Flat knit'!$B13,'Shipment status'!$H:$H,Y$3,'Shipment status'!$K:$K,'Flat knit'!$C13) | Z13: =SUMIFS('Shipment status'!$L:$L,'Shipment status'!$A:$A,'Flat knit'!$B13,'Shipment status'!$H:$H,Z$3,'Shipment status'!$K:$K,'Flat knit'!$C13) | AA13: =SUMIFS('Shipment status'!$L:$L,'Shipment status'!$A:$A,'Flat knit'!$B13,'Shipment status'!$H:$H,AA$3,'Shipment status'!$K:$K,'Flat knit'!$C13) | ... AK13: =SUMIFS('Shipment status'!$L:$L,'Shipment status'!$A:$A,'Flat knit'!$B13,'Shipment status'!$H:$H,AK$3,'Shipment status'!$K:$K,'Flat knit'!$C13)
A14: Signature White | B14: 1 | C14: S | D14: 2 | E14: 2 | F14: 2171 | G14: 5.22 | I14: =MAX(SUMIFS('Shipment status'!$L:$L,'Shipment status'!$A:$A,TRIM(CLEAN(SUBSTITUTE(VLOOKUP($B14&I$3,'PPO-GO'!$A:$AA,12,0)," ",""))),'Shipment status'!$H:$H,I$3,'Shipment status'!$K:$K,'Flat knit'!$C14),SUMIFS('Shipment status'!$L:$L,'Shipment status'!$A:$A,'Flat knit'!$B14,'Shipment status'!$H:$H,I$3,'Shipment status'!$K:$K,'Flat knit'!$C14)) | J14: =IFERROR(I14/$F14,"-") | L14: =MAX(SUMIFS('Shipment status'!$L:$L,'Shipment status'!$A:$A,TRIM(CLEAN(SUBSTITUTE(VLOOKUP($B14&L$3,'PPO-GO'!$A:$AA,12,0)," ",""))),'Shipment status'!$H:$H,L$3,'Shipment status'!$K:$K,'Flat knit'!$C14),SUMIFS('Shipment status'!$L:$L,'Shipment status'!$A:$A,'Flat knit'!$B14,'Shipment status'!$H:$H,L$3,'Shipment status'!$K:$K,'Flat knit'!$C14)) | M14: =IFERROR(IF(L14>I14*1.5,0.5,1)*L14/$F14,"-") | O14: =MAX(SUMIFS('Shipment status'!$L:$L,'Shipment status'!$A:$A,TRIM(CLEAN(SUBSTITUTE(VLOOKUP($B14,'PPO-GO'!$D:$L,9,0)," ",""))),'Shipment status'!$H:$H,O$3,'Shipment status'!$K:$K,'Flat knit'!$C14),SUMIFS('Shipment status'!$L:$L,'Shipment status'!$A:$A,'Flat knit'!$B14,'Shipment status'!$H:$H,O$3,'Shipment status'!$K:$K,'Flat knit'!$C14)) | P14: =IFERROR(O14/$F14,"-") | R14: =MAX(SUMIFS('Shipment status'!$L:$L,'Shipment status'!$A:$A,TRIM(CLEAN(SUBSTITUTE(VLOOKUP($B14,'PPO-GO'!$D:$L,9,0)," ",""))),'Shipment status'!$H:$H,R$3,'Shipment status'!$K:$K,'Flat knit'!$C14),SUMIFS('Shipment status'!$L:$L,'Shipment status'!$A:$A,'Flat knit'!$B14,'Shipment status'!$H:$H,R$3,'Shipment status'!$K:$K,'Flat knit'!$C14)) | S14: =IFERROR(R14/$F14,"-") | T14: =SUMIFS('Shipment status'!$L:$L,'Shipment status'!$A:$A,'Flat knit'!$B14,'Shipment status'!$H:$H,T$3,'Shipment status'!$K:$K,'Flat knit'!$C14) | U14: =SUMIFS('Shipment status'!$L:$L,'Shipment status'!$A:$A,'Flat knit'!$B14,'Shipment status'!$H:$H,U$3,'Shipment status'!$K:$K,'Flat knit'!$C14) | V14: =SUMIFS('Shipment status'!$L:$L,'Shipment status'!$A:$A,'Flat knit'!$B14,'Shipment status'!$H:$H,V$3,'Shipment status'!$K:$K,'Flat knit'!$C14) | W14: =SUMIFS('Shipment status'!$L:$L,'Shipment status'!$A:$A,'Flat knit'!$B14,'Shipment status'!$H:$H,W$3,'Shipment status'!$K:$K,'Flat knit'!$C14) | X14: =SUMIFS('Shipment status'!$L:$L,'Shipment status'!$A:$A,'Flat knit'!$B14,'Shipment status'!$H:$H,X$3,'Shipment status'!$K:$K,'Flat knit'!$C14) | Y14: =SUMIFS('Shipment status'!$L:$L,'Shipment status'!$A:$A,'Flat knit'!$B14,'Shipment status'!$H:$H,Y$3,'Shipment status'!$K:$K,'Flat knit'!$C14) | Z14: =SUMIFS('Shipment status'!$L:$L,'Shipment status'!$A:$A,'Flat knit'!$B14,'Shipment status'!$H:$H,Z$3,'Shipment status'!$K:$K,'Flat knit'!$C14) | AA14: =SUMIFS('Shipment status'!$L:$L,'Shipment status'!$A:$A,'Flat knit'!$B14,'Shipment status'!$H:$H,AA$3,'Shipment status'!$K:$K,'Flat knit'!$C14) | ... AK14: =SUMIFS('Shipment status'!$L:$L,'Shipment status'!$A:$A,'Flat knit'!$B14,'Shipment status'!$H:$H,AK$3,'Shipment status'!$K:$K,'Flat knit'!$C14)
A15: Signature White | B15: 1 | C15: M | D15: 2 | E15: 2 | F15: 3732 | G15: 18.32 | I15: =MAX(SUMIFS('Shipment status'!$L:$L,'Shipment status'!$A:$A,TRIM(CLEAN(SUBSTITUTE(VLOOKUP($B15&I$3,'PPO-GO'!$A:$AA,12,0)," ",""))),'Shipment status'!$H:$H,I$3,'Shipment status'!$K:$K,'Flat knit'!$C15),SUMIFS('Shipment status'!$L:$L,'Shipment status'!$A:$A,'Flat knit'!$B15,'Shipment status'!$H:$H,I$3,'Shipment status'!$K:$K,'Flat knit'!$C15)) | J15: =IFERROR(I15/$F15,"-") | L15: =MAX(SUMIFS('Shipment status'!$L:$L,'Shipment status'!$A:$A,TRIM(CLEAN(SUBSTITUTE(VLOOKUP($B15&L$3,'PPO-GO'!$A:$AA,12,0)," ",""))),'Shipment status'!$H:$H,L$3,'Shipment status'!$K:$K,'Flat knit'!$C15),SUMIFS('Shipment status'!$L:$L,'Shipment status'!$A:$A,'Flat knit'!$B15,'Shipment status'!$H:$H,L$3,'Shipment status'!$K:$K,'Flat knit'!$C15)) | M15: =IFERROR(IF(L15>I15*1.5,0.5,1)*L15/$F15,"-") | O15: =MAX(SUMIFS('Shipment status'!$L:$L,'Shipment status'!$A:$A,TRIM(CLEAN(SUBSTITUTE(VLOOKUP($B15,'PPO-GO'!$D:$L,9,0)," ",""))),'Shipment status'!$H:$H,O$3,'Shipment status'!$K:$K,'Flat knit'!$C15),SUMIFS('Shipment status'!$L:$L,'Shipment status'!$A:$A,'Flat knit'!$B15,'Shipment status'!$H:$H,O$3,'Shipment status'!$K:$K,'Flat knit'!$C15)) | P15: =IFERROR(O15/$F15,"-") | R15: =MAX(SUMIFS('Shipment status'!$L:$L,'Shipment status'!$A:$A,TRIM(CLEAN(SUBSTITUTE(VLOOKUP($B15,'PPO-GO'!$D:$L,9,0)," ",""))),'Shipment status'!$H:$H,R$3,'Shipment status'!$K:$K,'Flat knit'!$C15),SUMIFS('Shipment status'!$L:$L,'Shipment status'!$A:$A,'Flat knit'!$B15,'Shipment status'!$H:$H,R$3,'Shipment status'!$K:$K,'Flat knit'!$C15)) | S15: =IFERROR(R15/$F15,"-") | T15: =SUMIFS('Shipment status'!$L:$L,'Shipment status'!$A:$A,'Flat knit'!$B15,'Shipment status'!$H:$H,T$3,'Shipment status'!$K:$K,'Flat knit'!$C15) | U15: =SUMIFS('Shipment status'!$L:$L,'Shipment status'!$A:$A,'Flat knit'!$B15,'Shipment status'!$H:$H,U$3,'Shipment status'!$K:$K,'Flat knit'!$C15) | V15: =SUMIFS('Shipment status'!$L:$L,'Shipment status'!$A:$A,'Flat knit'!$B15,'Shipment status'!$H:$H,V$3,'Shipment status'!$K:$K,'Flat knit'!$C15) | W15: =SUMIFS('Shipment status'!$L:$L,'Shipment status'!$A:$A,'Flat knit'!$B15,'Shipment status'!$H:$H,W$3,'Shipment status'!$K:$K,'Flat knit'!$C15) | X15: =SUMIFS('Shipment status'!$L:$L,'Shipment status'!$A:$A,'Flat knit'!$B15,'Shipment status'!$H:$H,X$3,'Shipment status'!$K:$K,'Flat knit'!$C15) | Y15: =SUMIFS('Shipment status'!$L:$L,'Shipment status'!$A:$A,'Flat knit'!$B15,'Shipment status'!$H:$H,Y$3,'Shipment status'!$K:$K,'Flat knit'!$C15) | Z15: =SUMIFS('Shipment status'!$L:$L,'Shipment status'!$A:$A,'Flat knit'!$B15,'Shipment status'!$H:$H,Z$3,'Shipment status'!$K:$K,'Flat knit'!$C15) | AA15: =SUMIFS('Shipment status'!$L:$L,'Shipment status'!$A:$A,'Flat knit'!$B15,'Shipment status'!$H:$H,AA$3,'Shipment status'!$K:$K,'Flat knit'!$C15) | ... AK15: =SUMIFS('Shipment status'!$L:$L,'Shipment status'!$A:$A,'Flat knit'!$B15,'Shipment status'!$H:$H,AK$3,'Shipment status'!$K:$K,'Flat knit'!$C15)
A16: Signature White | B16: 1 | C16: L | D16: 2 | E16: 2 | F16: 4178 | G16: 22.54 | I16: =MAX(SUMIFS('Shipment status'!$L:$L,'Shipment status'!$A:$A,TRIM(CLEAN(SUBSTITUTE(VLOOKUP($B16&I$3,'PPO-GO'!$A:$AA,12,0)," ",""))),'Shipment status'!$H:$H,I$3,'Shipment status'!$K:$K,'Flat knit'!$C16),SUMIFS('Shipment status'!$L:$L,'Shipment status'!$A:$A,'Flat knit'!$B16,'Shipment status'!$H:$H,I$3,'Shipment status'!$K:$K,'Flat knit'!$C16)) | J16: =IFERROR(I16/$F16,"-") | K16: =IFERROR(J16/$F16,"-") | L16: =MAX(SUMIFS('Shipment status'!$L:$L,'Shipment status'!$A:$A,TRIM(CLEAN(SUBSTITUTE(VLOOKUP($B16&L$3,'PPO-GO'!$A:$AA,12,0)," ",""))),'Shipment status'!$H:$H,L$3,'Shipment status'!$K:$K,'Flat knit'!$C16),SUMIFS('Shipment status'!$L:$L,'Shipment status'!$A:$A,'Flat knit'!$B16,'Shipment status'!$H:$H,L$3,'Shipment status'!$K:$K,'Flat knit'!$C16)) | M16: =IFERROR(IF(L16>I16*1.5,0.5,1)*L16/$F16,"-") | O16: =MAX(SUMIFS('Shipment status'!$L:$L,'Shipment status'!$A:$A,TRIM(CLEAN(SUBSTITUTE(VLOOKUP($B16,'PPO-GO'!$D:$L,9,0)," ",""))),'Shipment status'!$H:$H,O$3,'Shipment status'!$K:$K,'Flat knit'!$C16),SUMIFS('Shipment status'!$L:$L,'Shipment status'!$A:$A,'Flat knit'!$B16,'Shipment status'!$H:$H,O$3,'Shipment status'!$K:$K,'Flat knit'!$C16)) | P16: =IFERROR(O16/$F16,"-") | R16: =MAX(SUMIFS('Shipment status'!$L:$L,'Shipment status'!$A:$A,TRIM(CLEAN(SUBSTITUTE(VLOOKUP($B16,'PPO-GO'!$D:$L,9,0)," ",""))),'Shipment status'!$H:$H,R$3,'Shipment status'!$K:$K,'Flat knit'!$C16),SUMIFS('Shipment status'!$L:$L,'Shipment status'!$A:$A,'Flat knit'!$B16,'Shipment status'!$H:$H,R$3,'Shipment status'!$K:$K,'Flat knit'!$C16)) | S16: =IFERROR(R16/$F16,"-") | T16: =SUMIFS('Shipment status'!$L:$L,'Shipment status'!$A:$A,'Flat knit'!$B16,'Shipment status'!$H:$H,T$3,'Shipment status'!$K:$K,'Flat knit'!$C16) | U16: =SUMIFS('Shipment status'!$L:$L,'Shipment status'!$A:$A,'Flat knit'!$B16,'Shipment status'!$H:$H,U$3,'Shipment status'!$K:$K,'Flat knit'!$C16) | V16: =SUMIFS('Shipment status'!$L:$L,'Shipment status'!$A:$A,'Flat knit'!$B16,'Shipment status'!$H:$H,V$3,'Shipment status'!$K:$K,'Flat knit'!$C16) | W16: =SUMIFS('Shipment status'!$L:$L,'Shipment status'!$A:$A,'Flat knit'!$B16,'Shipment status'!$H:$H,W$3,'Shipment status'!$K:$K,'Flat knit'!$C16) | X16: =SUMIFS('Shipment status'!$L:$L,'Shipment status'!$A:$A,'Flat knit'!$B16,'Shipment status'!$H:$H,X$3,'Shipment status'!$K:$K,'Flat knit'!$C16) | Y16: =SUMIFS('Shipment status'!$L:$L,'Shipment status'!$A:$A,'Flat knit'!$B16,'Shipment status'!$H:$H,Y$3,'Shipment status'!$K:$K,'Flat knit'!$C16) | Z16: =SUMIFS('Shipment status'!$L:$L,'Shipment status'!$A:$A,'Flat knit'!$B16,'Shipment status'!$H:$H,Z$3,'Shipment status'!$K:$K,'Flat knit'!$C16) | AA16: =SUMIFS('Shipment status'!$L:$L,'Shipment status'!$A:$A,'Flat knit'!$B16,'Shipment status'!$H:$H,AA$3,'Shipment status'!$K:$K,'Flat knit'!$C16) | ... AK16: =SUMIFS('Shipment status'!$L:$L,'Shipment status'!$A:$A,'Flat knit'!$B16,'Shipment status'!$H:$H,AK$3,'Shipment status'!$K:$K,'Flat knit'!$C16)
A17: Signature White | B17: 1 | C17: TTL | D17: 2 | E17: 2 | F17: 7370 | I17: =MAX(SUMIFS('Shipment status'!$L:$L,'Shipment status'!$A:$A,TRIM(CLEAN(SUBSTITUTE(VLOOKUP($B17&I$3,'PPO-GO'!$A:$AA,12,0)," ",""))),'Shipment status'!$H:$H,I$3,'Shipment status'!$K:$K,'Flat knit'!$C17),SUMIFS('Shipment status'!$L:$L,'Shipment status'!$A:$A,'Flat knit'!$B17,'Shipment status'!$H:$H,I$3,'Shipment status'!$K:$K,'Flat knit'!$C17)) | J17: =IFERROR(I17/$F17,"-") | K17: =IFERROR(J17/$F17,"-") | L17: =MAX(SUMIFS('Shipment status'!$L:$L,'Shipment status'!$A:$A,TRIM(CLEAN(SUBSTITUTE(VLOOKUP($B17&L$3,'PPO-GO'!$A:$AA,12,0)," ",""))),'Shipment status'!$H:$H,L$3,'Shipment status'!$K:$K,'Flat knit'!$C17),SUMIFS('Shipment status'!$L:$L,'Shipment status'!$A:$A,'Flat knit'!$B17,'Shipment status'!$H:$H,L$3,'Shipment status'!$K:$K,'Flat knit'!$C17)) | M17: =IFERROR(IF(L17>I17*1.5,0.5,1)*L17/$F17,"-") | O17: =MAX(SUMIFS('Shipment status'!$L:$L,'Shipment status'!$A:$A,TRIM(CLEAN(SUBSTITUTE(VLOOKUP($B17,'PPO-GO'!$D:$L,9,0)," ",""))),'Shipment status'!$H:$H,O$3,'Shipment status'!$K:$K,'Flat knit'!$C17),SUMIFS('Shipment status'!$L:$L,'Shipment status'!$A:$A,'Flat knit'!$B17,'Shipment status'!$H:$H,O$3,'Shipment status'!$K:$K,'Flat knit'!$C17)) | P17: =IFERROR(O17/$F17,"-") | R17: =MAX(SUMIFS('Shipment status'!$L:$L,'Shipment status'!$A:$A,TRIM(CLEAN(SUBSTITUTE(VLOOKUP($B17,'PPO-GO'!$D:$L,9,0)," ",""))),'Shipment status'!$H:$H,R$3,'Shipment status'!$K:$K,'Flat knit'!$C17),SUMIFS('Shipment status'!$L:$L,'Shipment status'!$A:$A,'Flat knit'!$B17,'Shipment status'!$H:$H,R$3,'Shipment status'!$K:$K,'Flat knit'!$C17)) | S17: =IFERROR(R17/$F17,"-") | T17: =SUMIFS('Shipment status'!$L:$L,'Shipment status'!$A:$A,'Flat knit'!$B17,'Shipment status'!$H:$H,T$3,'Shipment status'!$K:$K,'Flat knit'!$C17) | U17: =SUMIFS('Shipment status'!$L:$L,'Shipment status'!$A:$A,'Flat knit'!$B17,'Shipment status'!$H:$H,U$3,'Shipment status'!$K:$K,'Flat knit'!$C17) | V17: =SUMIFS('Shipment status'!$L:$L,'Shipment status'!$A:$A,'Flat knit'!$B17,'Shipment status'!$H:$H,V$3,'Shipment status'!$K:$K,'Flat knit'!$C17) | W17: =SUMIFS('Shipment status'!$L:$L,'Shipment status'!$A:$A,'Flat knit'!$B17,'Shipment status'!$H:$H,W$3,'Shipment status'!$K:$K,'Flat knit'!$C17) | X17: =SUMIFS('Shipment status'!$L:$L,'Shipment status'!$A:$A,'Flat knit'!$B17,'Shipment status'!$H:$H,X$3,'Shipment status'!$K:$K,'Flat knit'!$C17) | Y17: =SUMIFS('Shipment status'!$L:$L,'Shipment status'!$A:$A,'Flat knit'!$B17,'Shipment status'!$H:$H,Y$3,'Shipment status'!$K:$K,'Flat knit'!$C17) | Z17: =SUMIFS('Shipment status'!$L:$L,'Shipment status'!$A:$A,'Flat knit'!$B17,'Shipment status'!$H:$H,Z$3,'Shipment status'!$K:$K,'Flat knit'!$C17) | AA17: =SUMIFS('Shipment status'!$L:$L,'Shipment status'!$A:$A,'Flat knit'!$B17,'Shipment status'!$H:$H,AA$3,'Shipment status'!$K:$K,'Flat knit'!$C17) | ... AK17: =SUMIFS('Shipment status'!$L:$L,'Shipment status'!$A:$A,'Flat knit'!$B17,'Shipment status'!$H:$H,AK$3,'Shipment status'!$K:$K,'Flat knit'!$C17)
A18: Signature White | B18: 1 | C18: XXXL | D18: 2 | E18: 2 | F18: 402 | G18: 5.06 | I18: =MAX(SUMIFS('Shipment status'!$L:$L,'Shipment status'!$A:$A,TRIM(CLEAN(SUBSTITUTE(VLOOKUP($B18&I$3,'PPO-GO'!$A:$AA,12,0)," ",""))),'Shipment status'!$H:$H,I$3,'Shipment status'!$K:$K,'Flat knit'!$C18),SUMIFS('Shipment status'!$L:$L,'Shipment status'!$A:$A,'Flat knit'!$B18,'Shipment status'!$H:$H,I$3,'Shipment status'!$K:$K,'Flat knit'!$C18)) | J18: =IFERROR(I18/$F18,"-") | L18: =MAX(SUMIFS('Shipment status'!$L:$L,'Shipment status'!$A:$A,TRIM(CLEAN(SUBSTITUTE(VLOOKUP($B18&L$3,'PPO-GO'!$A:$AA,12,0)," ",""))),'Shipment status'!$H:$H,L$3,'Shipment status'!$K:$K,'Flat knit'!$C18),SUMIFS('Shipment status'!$L:$L,'Shipment status'!$A:$A,'Flat knit'!$B18,'Shipment status'!$H:$H,L$3,'Shipment status'!$K:$K,'Flat knit'!$C18)) | M18: =IFERROR(IF(L18>I18*1.5,0.5,1)*L18/$F18,"-") | O18: =MAX(SUMIFS('Shipment status'!$L:$L,'Shipment status'!$A:$A,TRIM(CLEAN(SUBSTITUTE(VLOOKUP($B18,'PPO-GO'!$D:$L,9,0)," ",""))),'Shipment status'!$H:$H,O$3,'Shipment status'!$K:$K,'Flat knit'!$C18),SUMIFS('Shipment status'!$L:$L,'Shipment status'!$A:$A,'Flat knit'!$B18,'Shipment status'!$H:$H,O$3,'Shipment status'!$K:$K,'Flat knit'!$C18)) | P18: =IFERROR(O18/$F18,"-") | R18: =MAX(SUMIFS('Shipment status'!$L:$L,'Shipment status'!$A:$A,TRIM(CLEAN(SUBSTITUTE(VLOOKUP($B18,'PPO-GO'!$D:$L,9,0)," ",""))),'Shipment status'!$H:$H,R$3,'Shipment status'!$K:$K,'Flat knit'!$C18),SUMIFS('Shipment status'!$L:$L,'Shipment status'!$A:$A,'Flat knit'!$B18,'Shipment status'!$H:$H,R$3,'Shipment status'!$K:$K,'Flat knit'!$C18)) | S18: =IFERROR(R18/$F18,"-") | T18: =SUMIFS('Shipment status'!$L:$L,'Shipment status'!$A:$A,'Flat knit'!$B18,'Shipment status'!$H:$H,T$3,'Shipment status'!$K:$K,'Flat knit'!$C18) | U18: =SUMIFS('Shipment status'!$L:$L,'Shipment status'!$A:$A,'Flat knit'!$B18,'Shipment status'!$H:$H,U$3,'Shipment status'!$K:$K,'Flat knit'!$C18) | V18: =SUMIFS('Shipment status'!$L:$L,'Shipment status'!$A:$A,'Flat knit'!$B18,'Shipment status'!$H:$H,V$3,'Shipment status'!$K:$K,'Flat knit'!$C18) | W18: =SUMIFS('Shipment status'!$L:$L,'Shipment status'!$A:$A,'Flat knit'!$B18,'Shipment status'!$H:$H,W$3,'Shipment status'!$K:$K,'Flat knit'!$C18) | X18: =SUMIFS('Shipment status'!$L:$L,'Shipment status'!$A:$A,'Flat knit'!$B18,'Shipment status'!$H:$H,X$3,'Shipment status'!$K:$K,'Flat knit'!$C18) | Y18: =SUMIFS('Shipment status'!$L:$L,'Shipment status'!$A:$A,'Flat knit'!$B18,'Shipment status'!$H:$H,Y$3,'Shipment status'!$K:$K,'Flat knit'!$C18) | Z18: =SUMIFS('Shipment status'!$L:$L,'Shipment status'!$A:$A,'Flat knit'!$B18,'Shipment status'!$H:$H,Z$3,'Shipment status'!$K:$K,'Flat knit'!$C18) | AA18: =SUMIFS('Shipment status'!$L:$L,'Shipment status'!$A:$A,'Flat knit'!$B18,'Shipment status'!$H:$H,AA$3,'Shipment status'!$K:$K,'Flat knit'!$C18) | ... AK18: =SUMIFS('Shipment status'!$L:$L,'Shipment status'!$A:$A,'Flat knit'!$B18,'Shipment status'!$H:$H,AK$3,'Shipment status'!$K:$K,'Flat knit'!$C18)
A19: Signature White | B19: 1 | C19: 2XL | D19: 2 | E19: 2 | F19: 1763 | G19: 8.5 | I19: =MAX(SUMIFS('Shipment status'!$L:$L,'Shipment status'!$A:$A,TRIM(CLEAN(SUBSTITUTE(VLOOKUP($B19&I$3,'PPO-GO'!$A:$AA,12,0)," ",""))),'Shipment status'!$H:$H,I$3,'Shipment status'!$K:$K,'Flat knit'!$C19),SUMIFS('Shipment status'!$L:$L,'Shipment status'!$A:$A,'Flat knit'!$B19,'Shipment status'!$H:$H,I$3,'Shipment status'!$K:$K,'Flat knit'!$C19)) | J19: =IFERROR(I19/$F19,"-") | L19: =MAX(SUMIFS('Shipment status'!$L:$L,'Shipment status'!$A:$A,TRIM(CLEAN(SUBSTITUTE(VLOOKUP($B19&L$3,'PPO-GO'!$A:$AA,12,0)," ",""))),'Shipment status'!$H:$H,L$3,'Shipment status'!$K:$K,'Flat knit'!$C19),SUMIFS('Shipment status'!$L:$L,'Shipment status'!$A:$A,'Flat knit'!$B19,'Shipment status'!$H:$H,L$3,'Shipment status'!$K:$K,'Flat knit'!$C19)) | M19: =IFERROR(IF(L19>I19*1.5,0.5,1)*L19/$F19,"-") | O19: =MAX(SUMIFS('Shipment status'!$L:$L,'Shipment status'!$A:$A,TRIM(CLEAN(SUBSTITUTE(VLOOKUP($B19,'PPO-GO'!$D:$L,9,0)," ",""))),'Shipment status'!$H:$H,O$3,'Shipment status'!$K:$K,'Flat knit'!$C19),SUMIFS('Shipment status'!$L:$L,'Shipment status'!$A:$A,'Flat knit'!$B19,'Shipment status'!$H:$H,O$3,'Shipment status'!$K:$K,'Flat knit'!$C19)) | P19: =IFERROR(O19/$F19,"-") | R19: =MAX(SUMIFS('Shipment status'!$L:$L,'Shipment status'!$A:$A,TRIM(CLEAN(SUBSTITUTE(VLOOKUP($B19,'PPO-GO'!$D:$L,9,0)," ",""))),'Shipment status'!$H:$H,R$3,'Shipment status'!$K:$K,'Flat knit'!$C19),SUMIFS('Shipment status'!$L:$L,'Shipment status'!$A:$A,'Flat knit'!$B19,'Shipment status'!$H:$H,R$3,'Shipment status'!$K:$K,'Flat knit'!$C19)) | S19: =IFERROR(R19/$F19,"-") | T19: =SUMIFS('Shipment status'!$L:$L,'Shipment status'!$A:$A,'Flat knit'!$B19,'Shipment status'!$H:$H,T$3,'Shipment status'!$K:$K,'Flat knit'!$C19) | U19: =SUMIFS('Shipment status'!$L:$L,'Shipment status'!$A:$A,'Flat knit'!$B19,'Shipment status'!$H:$H,U$3,'Shipment status'!$K:$K,'Flat knit'!$C19) | V19: =SUMIFS('Shipment status'!$L:$L,'Shipment status'!$A:$A,'Flat knit'!$B19,'Shipment status'!$H:$H,V$3,'Shipment status'!$K:$K,'Flat knit'!$C19) | W19: =SUMIFS('Shipment status'!$L:$L,'Shipment status'!$A:$A,'Flat knit'!$B19,'Shipment status'!$H:$H,W$3,'Shipment status'!$K:$K,'Flat knit'!$C19) | X19: =SUMIFS('Shipment status'!$L:$L,'Shipment status'!$A:$A,'Flat knit'!$B19,'Shipment status'!$H:$H,X$3,'Shipment status'!$K:$K,'Flat knit'!$C19) | Y19: =SUMIFS('Shipment status'!$L:$L,'Shipment status'!$A:$A,'Flat knit'!$B19,'Shipment status'!$H:$H,Y$3,'Shipment status'!$K:$K,'Flat knit'!$C19) | Z19: =SUMIFS('Shipment status'!$L:$L,'Shipment status'!$A:$A,'Flat knit'!$B19,'Shipment status'!$H:$H,Z$3,'Shipment status'!$K:$K,'Flat knit'!$C19) | AA19: =SUMIFS('Shipment status'!$L:$L,'Shipment status'!$A:$A,'Flat knit'!$B19,'Shipment status'!$H:$H,AA$3,'Shipment status'!$K:$K,'Flat knit'!$C19) | ... AK19: =SUMIFS('Shipment status'!$L:$L,'Shipment status'!$A:$A,'Flat knit'!$B19,'Shipment status'!$H:$H,AK$3,'Shipment status'!$K:$K,'Flat knit'!$C19)
A20: Signature Black | B20: 9 | C20: XL | D20: 2 | E20: 2 | F20: 2506 | G20: 13.02 | I20: =MAX(SUMIFS('Shipment status'!$L:$L,'Shipment status'!$A:$A,TRIM(CLEAN(SUBSTITUTE(VLOOKUP($B20&I$3,'PPO-GO'!$A:$AA,12,0)," ",""))),'Shipment status'!$H:$H,I$3,'Shipment status'!$K:$K,'Flat knit'!$C20),SUMIFS('Shipment status'!$L:$L,'Shipment status'!$A:$A,'Flat knit'!$B20,'Shipment status'!$H:$H,I$3,'Shipment status'!$K:$K,'Flat knit'!$C20)) | J20: =IFERROR(I20/$F20,"-") | L20: =MAX(SUMIFS('Shipment status'!$L:$L,'Shipment status'!$A:$A,TRIM(CLEAN(SUBSTITUTE(VLOOKUP($B20&L$3,'PPO-GO'!$A:$AA,12,0)," ",""))),'Shipment status'!$H:$H,L$3,'Shipment status'!$K:$K,'Flat knit'!$C20),SUMIFS('Shipment status'!$L:$L,'Shipment status'!$A:$A,'Flat knit'!$B20,'Shipment status'!$H:$H,L$3,'Shipment status'!$K:$K,'Flat knit'!$C20)) | M20: =IFERROR(IF(L20>I20*1.5,0.5,1)*L20/$F20,"-") | O20: =MAX(SUMIFS('Shipment status'!$L:$L,'Shipment status'!$A:$A,TRIM(CLEAN(SUBSTITUTE(VLOOKUP($B20,'PPO-GO'!$D:$L,9,0)," ",""))),'Shipment status'!$H:$H,O$3,'Shipment status'!$K:$K,'Flat knit'!$C20),SUMIFS('Shipment status'!$L:$L,'Shipment status'!$A:$A,'Flat knit'!$B20,'Shipment status'!$H:$H,O$3,'Shipment status'!$K:$K,'Flat knit'!$C20)) | P20: =IFERROR(O20/$F20,"-") | R20: =MAX(SUMIFS('Shipment status'!$L:$L,'Shipment status'!$A:$A,TRIM(CLEAN(SUBSTITUTE(VLOOKUP($B20,'PPO-GO'!$D:$L,9,0)," ",""))),'Shipment status'!$H:$H,R$3,'Shipment status'!$K:$K,'Flat knit'!$C20),SUMIFS('Shipment status'!$L:$L,'Shipment status'!$A:$A,'Flat knit'!$B20,'Shipment status'!$H:$H,R$3,'Shipment status'!$K:$K,'Flat knit'!$C20)) | S20: =IFERROR(R20/$F20,"-") | T20: =SUMIFS('Shipment status'!$L:$L,'Shipment status'!$A:$A,'Flat knit'!$B20,'Shipment status'!$H:$H,T$3,'Shipment status'!$K:$K,'Flat knit'!$C20) | U20: =SUMIFS('Shipment status'!$L:$L,'Shipment status'!$A:$A,'Flat knit'!$B20,'Shipment status'!$H:$H,U$3,'Shipment status'!$K:$K,'Flat knit'!$C20) | V20: =SUMIFS('Shipment status'!$L:$L,'Shipment status'!$A:$A,'Flat knit'!$B20,'Shipment status'!$H:$H,V$3,'Shipment status'!$K:$K,'Flat knit'!$C20) | W20: =SUMIFS('Shipment status'!$L:$L,'Shipment status'!$A:$A,'Flat knit'!$B20,'Shipment status'!$H:$H,W$3,'Shipment status'!$K:$K,'Flat knit'!$C20) | X20: =SUMIFS('Shipment status'!$L:$L,'Shipment status'!$A:$A,'Flat knit'!$B20,'Shipment status'!$H:$H,X$3,'Shipment status'!$K:$K,'Flat knit'!$C20) | Y20: =SUMIFS('Shipment status'!$L:$L,'Shipment status'!$A:$A,'Flat knit'!$B20,'Shipment status'!$H:$H,Y$3,'Shipment status'!$K:$K,'Flat knit'!$C20) | Z20: =SUMIFS('Shipment status'!$L:$L,'Shipment status'!$A:$A,'Flat knit'!$B20,'Shipment status'!$H:$H,Z$3,'Shipment status'!$K:$K,'Flat knit'!$C20) | AA20: =SUMIFS('Shipment status'!$L:$L,'Shipment status'!$A:$A,'Flat knit'!$B20,'Shipment status'!$H:$H,AA$3,'Shipment status'!$K:$K,'Flat knit'!$C20) | ... AK20: =SUMIFS('Shipment status'!$L:$L,'Shipment status'!$A:$A,'Flat knit'!$B20,'Shipment status'!$H:$H,AK$3,'Shipment status'!$K:$K,'Flat knit'!$C20)
A21: Signature Black | B21: 9 | C21: S | D21: 2 | E21: 2 | F21: 1372 | G21: 3.38 | I21: =MAX(SUMIFS('Shipment status'!$L:$L,'Shipment status'!$A:$A,TRIM(CLEAN(SUBSTITUTE(VLOOKUP($B21&I$3,'PPO-GO'!$A:$AA,12,0)," ",""))),'Shipment status'!$H:$H,I$3,'Shipment status'!$K:$K,'Flat knit'!$C21),SUMIFS('Shipment status'!$L:$L,'Shipment status'!$A:$A,'Flat knit'!$B21,'Shipment status'!$H:$H,I$3,'Shipment status'!$K:$K,'Flat knit'!$C21)) | J21: =IFERROR(I21/$F21,"-") | L21: =MAX(SUMIFS('Shipment status'!$L:$L,'Shipment status'!$A:$A,TRIM(CLEAN(SUBSTITUTE(VLOOKUP($B21&L$3,'PPO-GO'!$A:$AA,12,0)," ",""))),'Shipment status'!$H:$H,L$3,'Shipment status'!$K:$K,'Flat knit'!$C21),SUMIFS('Shipment status'!$L:$L,'Shipment status'!$A:$A,'Flat knit'!$B21,'Shipment status'!$H:$H,L$3,'Shipment status'!$K:$K,'Flat knit'!$C21)) | M21: =IFERROR(IF(L21>I21*1.5,0.5,1)*L21/$F21,"-") | O21: =MAX(SUMIFS('Shipment status'!$L:$L,'Shipment status'!$A:$A,TRIM(CLEAN(SUBSTITUTE(VLOOKUP($B21,'PPO-GO'!$D:$L,9,0)," ",""))),'Shipment status'!$H:$H,O$3,'Shipment status'!$K:$K,'Flat knit'!$C21),SUMIFS('Shipment status'!$L:$L,'Shipment status'!$A:$A,'Flat knit'!$B21,'Shipment status'!$H:$H,O$3,'Shipment status'!$K:$K,'Flat knit'!$C21)) | P21: =IFERROR(O21/$F21,"-") | R21: =MAX(SUMIFS('Shipment status'!$L:$L,'Shipment status'!$A:$A,TRIM(CLEAN(SUBSTITUTE(VLOOKUP($B21,'PPO-GO'!$D:$L,9,0)," ",""))),'Shipment status'!$H:$H,R$3,'Shipment status'!$K:$K,'Flat knit'!$C21),SUMIFS('Shipment status'!$L:$L,'Shipment status'!$A:$A,'Flat knit'!$B21,'Shipment status'!$H:$H,R$3,'Shipment status'!$K:$K,'Flat knit'!$C21)) | S21: =IFERROR(R21/$F21,"-") | T21: =SUMIFS('Shipment status'!$L:$L,'Shipment status'!$A:$A,'Flat knit'!$B21,'Shipment status'!$H:$H,T$3,'Shipment status'!$K:$K,'Flat knit'!$C21) | U21: =SUMIFS('Shipment status'!$L:$L,'Shipment status'!$A:$A,'Flat knit'!$B21,'Shipment status'!$H:$H,U$3,'Shipment status'!$K:$K,'Flat knit'!$C21) | V21: =SUMIFS('Shipment status'!$L:$L,'Shipment status'!$A:$A,'Flat knit'!$B21,'Shipment status'!$H:$H,V$3,'Shipment status'!$K:$K,'Flat knit'!$C21) | W21: =SUMIFS('Shipment status'!$L:$L,'Shipment status'!$A:$A,'Flat knit'!$B21,'Shipment status'!$H:$H,W$3,'Shipment status'!$K:$K,'Flat knit'!$C21) | X21: =SUMIFS('Shipment status'!$L:$L,'Shipment status'!$A:$A,'Flat knit'!$B21,'Shipment status'!$H:$H,X$3,'Shipment status'!$K:$K,'Flat knit'!$C21) | Y21: =SUMIFS('Shipment status'!$L:$L,'Shipment status'!$A:$A,'Flat knit'!$B21,'Shipment status'!$H:$H,Y$3,'Shipment status'!$K:$K,'Flat knit'!$C21) | Z21: =SUMIFS('Shipment status'!$L:$L,'Shipment status'!$A:$A,'Flat knit'!$B21,'Shipment status'!$H:$H,Z$3,'Shipment status'!$K:$K,'Flat knit'!$C21) | AA21: =SUMIFS('Shipment status'!$L:$L,'Shipment status'!$A:$A,'Flat knit'!$B21,'Shipment status'!$H:$H,AA$3,'Shipment status'!$K:$K,'Flat knit'!$C21) | ... AK21: =SUMIFS('Shipment status'!$L:$L,'Shipment status'!$A:$A,'Flat knit'!$B21,'Shipment status'!$H:$H,AK$3,'Shipment status'!$K:$K,'Flat knit'!$C21)
A22: Signature Black | B22: 9 | C22: M | D22: 2 | E22: 2 | F22: 2622 | G22: 12.24 | I22: =MAX(SUMIFS('Shipment status'!$L:$L,'Shipment status'!$A:$A,TRIM(CLEAN(SUBSTITUTE(VLOOKUP($B22&I$3,'PPO-GO'!$A:$AA,12,0)," ",""))),'Shipment status'!$H:$H,I$3,'Shipment status'!$K:$K,'Flat knit'!$C22),SUMIFS('Shipment status'!$L:$L,'Shipment status'!$A:$A,'Flat knit'!$B22,'Shipment status'!$H:$H,I$3,'Shipment status'!$K:$K,'Flat knit'!$C22)) | J22: =IFERROR(I22/$F22,"-") | L22: =MAX(SUMIFS('Shipment status'!$L:$L,'Shipment status'!$A:$A,TRIM(CLEAN(SUBSTITUTE(VLOOKUP($B22&L$3,'PPO-GO'!$A:$AA,12,0)," ",""))),'Shipment status'!$H:$H,L$3,'Shipment status'!$K:$K,'Flat knit'!$C22),SUMIFS('Shipment status'!$L:$L,'Shipment status'!$A:$A,'Flat knit'!$B22,'Shipment status'!$H:$H,L$3,'Shipment status'!$K:$K,'Flat knit'!$C22)) | M22: =IFERROR(IF(L22>I22*1.5,0.5,1)*L22/$F22,"-") | O22: =MAX(SUMIFS('Shipment status'!$L:$L,'Shipment status'!$A:$A,TRIM(CLEAN(SUBSTITUTE(VLOOKUP($B22,'PPO-GO'!$D:$L,9,0)," ",""))),'Shipment status'!$H:$H,O$3,'Shipment status'!$K:$K,'Flat knit'!$C22),SUMIFS('Shipment status'!$L:$L,'Shipment status'!$A:$A,'Flat knit'!$B22,'Shipment status'!$H:$H,O$3,'Shipment status'!$K:$K,'Flat knit'!$C22)) | P22: =IFERROR(O22/$F22,"-") | R22: =MAX(SUMIFS('Shipment status'!$L:$L,'Shipment status'!$A:$A,TRIM(CLEAN(SUBSTITUTE(VLOOKUP($B22,'PPO-GO'!$D:$L,9,0)," ",""))),'Shipment status'!$H:$H,R$3,'Shipment status'!$K:$K,'Flat knit'!$C22),SUMIFS('Shipment status'!$L:$L,'Shipment status'!$A:$A,'Flat knit'!$B22,'Shipment status'!$H:$H,R$3,'Shipment status'!$K:$K,'Flat knit'!$C22)) | S22: =IFERROR(R22/$F22,"-") | T22: =SUMIFS('Shipment status'!$L:$L,'Shipment status'!$A:$A,'Flat knit'!$B22,'Shipment status'!$H:$H,T$3,'Shipment status'!$K:$K,'Flat knit'!$C22) | U22: =SUMIFS('Shipment status'!$L:$L,'Shipment status'!$A:$A,'Flat knit'!$B22,'Shipment status'!$H:$H,U$3,'Shipment status'!$K:$K,'Flat knit'!$C22) | V22: =SUMIFS('Shipment status'!$L:$L,'Shipment status'!$A:$A,'Flat knit'!$B22,'Shipment status'!$H:$H,V$3,'Shipment status'!$K:$K,'Flat knit'!$C22) | W22: =SUMIFS('Shipment status'!$L:$L,'Shipment status'!$A:$A,'Flat knit'!$B22,'Shipment status'!$H:$H,W$3,'Shipment status'!$K:$K,'Flat knit'!$C22) | X22: =SUMIFS('Shipment status'!$L:$L,'Shipment status'!$A:$A,'Flat knit'!$B22,'Shipment status'!$H:$H,X$3,'Shipment status'!$K:$K,'Flat knit'!$C22) | Y22: =SUMIFS('Shipment status'!$L:$L,'Shipment status'!$A:$A,'Flat knit'!$B22,'Shipment status'!$H:$H,Y$3,'Shipment status'!$K:$K,'Flat knit'!$C22) | Z22: =SUMIFS('Shipment status'!$L:$L,'Shipment status'!$A:$A,'Flat knit'!$B22,'Shipment status'!$H:$H,Z$3,'Shipment status'!$K:$K,'Flat knit'!$C22) | AA22: =SUMIFS('Shipment status'!$L:$L,'Shipment status'!$A:$A,'Flat knit'!$B22,'Shipment status'!$H:$H,AA$3,'Shipment status'!$K:$K,'Flat knit'!$C22) | ... AK22: =SUMIFS('Shipment status'!$L:$L,'Shipment status'!$A:$A,'Flat knit'!$B22,'Shipment status'!$H:$H,AK$3,'Shipment status'!$K:$K,'Flat knit'!$C22)
A23: Signature Black | B23: 9 | C23: L | D23: 2 | E23: 2 | F23: 3205 | G23: 16.1 | I23: =MAX(SUMIFS('Shipment status'!$L:$L,'Shipment status'!$A:$A,TRIM(CLEAN(SUBSTITUTE(VLOOKUP($B23&I$3,'PPO-GO'!$A:$AA,12,0)," ",""))),'Shipment status'!$H:$H,I$3,'Shipment status'!$K:$K,'Flat knit'!$C23),SUMIFS('Shipment status'!$L:$L,'Shipment status'!$A:$A,'Flat knit'!$B23,'Shipment status'!$H:$H,I$3,'Shipment status'!$K:$K,'Flat knit'!$C23)) | J23: =IFERROR(I23/$F23,"-") | L23: =MAX(SUMIFS('Shipment status'!$L:$L,'Shipment status'!$A:$A,TRIM(CLEAN(SUBSTITUTE(VLOOKUP($B23&L$3,'PPO-GO'!$A:$AA,12,0)," ",""))),'Shipment status'!$H:$H,L$3,'Shipment status'!$K:$K,'Flat knit'!$C23),SUMIFS('Shipment status'!$L:$L,'Shipment status'!$A:$A,'Flat knit'!$B23,'Shipment status'!$H:$H,L$3,'Shipment status'!$K:$K,'Flat knit'!$C23)) | M23: =IFERROR(IF(L23>I23*1.5,0.5,1)*L23/$F23,"-") | O23: =MAX(SUMIFS('Shipment status'!$L:$L,'Shipment status'!$A:$A,TRIM(CLEAN(SUBSTITUTE(VLOOKUP($B23,'PPO-GO'!$D:$L,9,0)," ",""))),'Shipment status'!$H:$H,O$3,'Shipment status'!$K:$K,'Flat knit'!$C23),SUMIFS('Shipment status'!$L:$L,'Shipment status'!$A:$A,'Flat knit'!$B23,'Shipment status'!$H:$H,O$3,'Shipment status'!$K:$K,'Flat knit'!$C23)) | P23: =IFERROR(O23/$F23,"-") | R23: =MAX(SUMIFS('Shipment status'!$L:$L,'Shipment status'!$A:$A,TRIM(CLEAN(SUBSTITUTE(VLOOKUP($B23,'PPO-GO'!$D:$L,9,0)," ",""))),'Shipment status'!$H:$H,R$3,'Shipment status'!$K:$K,'Flat knit'!$C23),SUMIFS('Shipment status'!$L:$L,'Shipment status'!$A:$A,'Flat knit'!$B23,'Shipment status'!$H:$H,R$3,'Shipment status'!$K:$K,'Flat knit'!$C23)) | S23: =IFERROR(R23/$F23,"-") | T23: =SUMIFS('Shipment status'!$L:$L,'Shipment status'!$A:$A,'Flat knit'!$B23,'Shipment status'!$H:$H,T$3,'Shipment status'!$K:$K,'Flat knit'!$C23) | U23: =SUMIFS('Shipment status'!$L:$L,'Shipment status'!$A:$A,'Flat knit'!$B23,'Shipment status'!$H:$H,U$3,'Shipment status'!$K:$K,'Flat knit'!$C23) | V23: =SUMIFS('Shipment status'!$L:$L,'Shipment status'!$A:$A,'Flat knit'!$B23,'Shipment status'!$H:$H,V$3,'Shipment status'!$K:$K,'Flat knit'!$C23) | W23: =SUMIFS('Shipment status'!$L:$L,'Shipment status'!$A:$A,'Flat knit'!$B23,'Shipment status'!$H:$H,W$3,'Shipment status'!$K:$K,'Flat knit'!$C23) | X23: =SUMIFS('Shipment status'!$L:$L,'Shipment status'!$A:$A,'Flat knit'!$B23,'Shipment status'!$H:$H,X$3,'Shipment status'!$K:$K,'Flat knit'!$C23) | Y23: =SUMIFS('Shipment status'!$L:$L,'Shipment status'!$A:$A,'Flat knit'!$B23,'Shipment status'!$H:$H,Y$3,'Shipment status'!$K:$K,'Flat knit'!$C23) | Z23: =SUMIFS('Shipment status'!$L:$L,'Shipment status'!$A:$A,'Flat knit'!$B23,'Shipment status'!$H:$H,Z$3,'Shipment status'!$K:$K,'Flat knit'!$C23) | AA23: =SUMIFS('Shipment status'!$L:$L,'Shipment status'!$A:$A,'Flat knit'!$B23,'Shipment status'!$H:$H,AA$3,'Shipment status'!$K:$K,'Flat knit'!$C23) | ... AK23: =SUMIFS('Shipment status'!$L:$L,'Shipment status'!$A:$A,'Flat knit'!$B23,'Shipment status'!$H:$H,AK$3,'Shipment status'!$K:$K,'Flat knit'!$C23)
